Workbook

Sheet COMPARATIVO
A1: COMPARATIVO DE CENÁRIOS — POSSIBILIDADES REAIS DE REDUÇÃO
A3: ="READEQUAÇÃO DE MARGEM — "&IF(CONTRACHEQUE!$B$3="","[CLIENTE]",UPPER(CONTRACHEQUE!$B$3))&IF(CONTRACHEQUE!$B$5="",""," — COMPETÊNCIA "&CONTRACHEQUE!$B$5) -> READEQUAÇÃO DE MARGEM — [CLIENTE] | Z3: Fator A
Z4: =IF($B$15=0,1,MIN(1,$B$8*'SE 40%'!$H$24/$B$15)) -> 1
A5: 1. BASE DE CÁLCULO
A6: Renda bruta (proventos) | B6: ='SE 40%'!B4 -> 0
A7: (–) Descontos obrigatórios | B7: ='SE 40%'!B6 -> 0
A8: (=) Renda líquida — base da margem | B8: ='SE 40%'!B8 -> 0
A10: 2. CONSIGNAÇÕES POR MODALIDADE — COMO CADA TESE AS TRATA
A11: Modalidade | B11: Desconto atual | C11: % da renda líquida | D11: Cenário A — após (teto global 40%) | E11: Cenário B — margem (%) | F11: Cenário B — margem (R$) | G11: Cenário B — após (35% + 5%)
A12: EMPRÉSTIMO CONSIGNADO | B12: =SUMIF(CONTRACHEQUE!$G$8:$G$87,"EMPRÉSTIMO CONSIGNADO",CONTRACHEQUE!$D$8:$D$87) -> 0 | C12: =IF($B$8=0,0,B12/$B$8) -> 0 | D12: =B12*$Z$4 -> 0 | E12: ='SE 35-5'!J5 -> 0.35 | F12: =$B$8*E12 -> 0 | G12: =B12*Z12 -> 0 | Z12: =IF(B12+B14=0,1,MIN(1,F12/(B12+B14))) -> 1
A13: CARTÃO CONSIGNADO | B13: =SUMIF(CONTRACHEQUE!$G$8:$G$87,"CARTÃO CONSIGNADO",CONTRACHEQUE!$D$8:$D$87) -> 0 | C13: =IF($B$8=0,0,B13/$B$8) -> 0 | D13: =B13*$Z$4 -> 0 | E13: ='SE 35-5'!J6 -> 0.05 | F13: =$B$8*E13 -> 0 | G13: =MIN(B13,F13) -> 0 | Z13: =IF(B13=0,1,MIN(1,F13/B13)) -> 1
A14: CARTÃO BENEFÍCIO | B14: =SUMIF(CONTRACHEQUE!$G$8:$G$87,"CARTÃO BENEFÍCIO",CONTRACHEQUE!$D$8:$D$87) -> 0 | C14: =IF($B$8=0,0,B14/$B$8) -> 0 | D14: =B14*$Z$4 -> 0 | E14: ='SE 35-5'!J7 -> 0.35 | F14: ="(incl. nos 35%)" -> (incl. nos 35%) | G14: =B14*Z14 -> 0 | Z14: =Z12 -> 1
A15: TOTAL | B15: =SUM(B12:B14) -> 0 | C15: =IF($B$8=0,0,B15/$B$8) -> 0 | D15: =SUM(D12:D14) -> 0 | E15: =E12+E13 -> 0.4 | F15: =SUM(F12:F14) -> 0 | G15: =SUM(G12:G14) -> 0
A17: 3. QUADRO-RESUMO PARA A REUNIÃO
A18: Indicador | B18: Situação atual | C18: CENÁRIO A — Teto global 40% | D18: CENÁRIO B — Margens 35% + 5%
A19: Desconto mensal com consignações | B19: =B15 -> 0 | C19: =D15 -> 0 | D19: =G15 -> 0
A20: Comprometimento da renda líquida | B20: =IF($B$8=0,0,B19/$B$8) -> 0 | C20: =IF($B$8=0,0,C19/$B$8) -> 0 | D20: =IF($B$8=0,0,D19/$B$8) -> 0
A21: REDUÇÃO MENSAL DA PRESTAÇÃO | B21: 0 | C21: =$B$19-C19 -> 0 | D21: =$B$19-D19 -> 0
A22: Redução acumulada em 12 meses | B22: 0 | C22: =C21*12 -> 0 | D22: =D21*12 -> 0
A23: Renda livre mensal | B23: =$B$8-B19 -> 0 | C23: =$B$8-C19 -> 0 | D23: =$B$8-D19 -> 0
A24: Aumento da renda livre | B24: 0 | C24: =IF($B$23<=0,0,C21/$B$23) -> 0 | D24: =IF($B$23<=0,0,D21/$B$23) -> 0
A25: Potencial de restituição em dobro (por 12 meses de excesso) | B25: 0 | C25: =C21*12*2 -> 0 | D25: =D21*12*2 -> 0
A27: =IF($B$15=0,"Preencha a aba CONTRACHEQUE para gerar a comparação entre as teses.",IF(AND(C21=0,D21=0),"Nenhuma das teses gera redução: as consignações já estão dentro dos limites legais.",IF(ROUND(C21-D21,2)=0,"As duas teses produzem a MESMA redução: R$ "&FIXED(C21,2)&" por mês (R$ "&FIXED(C22,2)&" em 12 meses).","Tese mais favorável ao cliente: "&IF(C21>D21,"CENÁRIO A (teto global de 40%)","CENÁRIO B (margens 35% + 5%)")&" — redução de R$ "&FIXED(MAX(C21,D21),2)&"/mês. Se o juízo adotar a outra tese, a redução será de R$ "&FIXED(MIN(C21,D21),2)&"/mês. Diferença entre as teses: R$ "&FIXED(ABS(C21-D21),2)&"/mês (R$ "&FIXED(ABS(C22-D22),2)&" em 12 meses)."))) -> Preencha a aba CONTRACHEQUE para gerar a comparação entre as teses.
A31: 4. PROJEÇÃO POR CONTRATO / RUBRICA
A32: Rubrica / Instituição | B32: Modalidade | C32: Desconto atual | D32: Cenário A — nova parcela | E32: Cenário A — redução | F32: Cenário B — nova parcela | G32: Cenário B — redução
A33: {=IFERROR(INDEX(CONTRACHEQUE!$B$8:$B$87,MATCH(1,CONTRACHEQUE!$I$8:$I$87,0)),"")} | B33: {=IFERROR(INDEX(CONTRACHEQUE!$G$8:$G$87,MATCH(1,CONTRACHEQUE!$I$8:$I$87,0)),"")} | C33: {=IFERROR(INDEX(CONTRACHEQUE!$D$8:$D$87,MATCH(1,CONTRACHEQUE!$I$8:$I$87,0)),"")} | D33: =IF(C33="","",C33*$Z$4) | E33: =IF(C33="","",C33-D33) | F33: =IF(C33="","",C33*INDEX($Z$12:$Z$14,MATCH(B33,$A$12:$A$14,0))) | G33: =IF(C33="","",C33-F33)
A34: {=IFERROR(INDEX(CONTRACHEQUE!$B$8:$B$87,MATCH(2,CONTRACHEQUE!$I$8:$I$87,0)),"")} | B34: {=IFERROR(INDEX(CONTRACHEQUE!$G$8:$G$87,MATCH(2,CONTRACHEQUE!$I$8:$I$87,0)),"")} | C34: {=IFERROR(INDEX(CONTRACHEQUE!$D$8:$D$87,MATCH(2,CONTRACHEQUE!$I$8:$I$87,0)),"")} | D34: =IF(C34="","",C34*$Z$4) | E34: =IF(C34="","",C34-D34) | F34: =IF(C34="","",C34*INDEX($Z$12:$Z$14,MATCH(B34,$A$12:$A$14,0))) | G34: =IF(C34="","",C34-F34)
A35: {=IFERROR(INDEX(CONTRACHEQUE!$B$8:$B$87,MATCH(3,CONTRACHEQUE!$I$8:$I$87,0)),"")} | B35: {=IFERROR(INDEX(CONTRACHEQUE!$G$8:$G$87,MATCH(3,CONTRACHEQUE!$I$8:$I$87,0)),"")} | C35: {=IFERROR(INDEX(CONTRACHEQUE!$D$8:$D$87,MATCH(3,CONTRACHEQUE!$I$8:$I$87,0)),"")} | D35: =IF(C35="","",C35*$Z$4) | E35: =IF(C35="","",C35-D35) | F35: =IF(C35="","",C35*INDEX($Z$12:$Z$14,MATCH(B35,$A$12:$A$14,0))) | G35: =IF(C35="","",C35-F35)
A36: {=IFERROR(INDEX(CONTRACHEQUE!$B$8:$B$87,MATCH(4,CONTRACHEQUE!$I$8:$I$87,0)),"")} | B36: {=IFERROR(INDEX(CONTRACHEQUE!$G$8:$G$87,MATCH(4,CONTRACHEQUE!$I$8:$I$87,0)),"")} | C36: {=IFERROR(INDEX(CONTRACHEQUE!$D$8:$D$87,MATCH(4,CONTRACHEQUE!$I$8:$I$87,0)),"")} | D36: =IF(C36="","",C36*$Z$4) | E36: =IF(C36="","",C36-D36) | F36: =IF(C36="","",C36*INDEX($Z$12:$Z$14,MATCH(B36,$A$12:$A$14,0))) | G36: =IF(C36="","",C36-F36)
A37: {=IFERROR(INDEX(CONTRACHEQUE!$B$8:$B$87,MATCH(5,CONTRACHEQUE!$I$8:$I$87,0)),"")} | B37: {=IFERROR(INDEX(CONTRACHEQUE!$G$8:$G$87,MATCH(5,CONTRACHEQUE!$I$8:$I$87,0)),"")} | C37: {=IFERROR(INDEX(CONTRACHEQUE!$D$8:$D$87,MATCH(5,CONTRACHEQUE!$I$8:$I$87,0)),"")} | D37: =IF(C37="","",C37*$Z$4) | E37: =IF(C37="","",C37-D37) | F37: =IF(C37="","",C37*INDEX($Z$12:$Z$14,MATCH(B37,$A$12:$A$14,0))) | G37: =IF(C37="","",C37-F37)
A38: {=IFERROR(INDEX(CONTRACHEQUE!$B$8:$B$87,MATCH(6,CONTRACHEQUE!$I$8:$I$87,0)),"")} | B38: {=IFERROR(INDEX(CONTRACHEQUE!$G$8:$G$87,MATCH(6,CONTRACHEQUE!$I$8:$I$87,0)),"")} | C38: {=IFERROR(INDEX(CONTRACHEQUE!$D$8:$D$87,MATCH(6,CONTRACHEQUE!$I$8:$I$87,0)),"")} | D38: =IF(C38="","",C38*$Z$4) | E38: =IF(C38="","",C38-D38) | F38: =IF(C38="","",C38*INDEX($Z$12:$Z$14,MATCH(B38,$A$12:$A$14,0))) | G38: =IF(C38="","",C38-F38)
A39: {=IFERROR(INDEX(CONTRACHEQUE!$B$8:$B$87,MATCH(7,CONTRACHEQUE!$I$8:$I$87,0)),"")} | B39: {=IFERROR(INDEX(CONTRACHEQUE!$G$8:$G$87,MATCH(7,CONTRACHEQUE!$I$8:$I$87,0)),"")} | C39: {=IFERROR(INDEX(CONTRACHEQUE!$D$8:$D$87,MATCH(7,CONTRACHEQUE!$I$8:$I$87,0)),"")} | D39: =IF(C39="","",C39*$Z$4) | E39: =IF(C39="","",C39-D39) | F39: =IF(C39="","",C39*INDEX($Z$12:$Z$14,MATCH(B39,$A$12:$A$14,0))) | G39: =IF(C39="","",C39-F39)
A40: {=IFERROR(INDEX(CONTRACHEQUE!$B$8:$B$87,MATCH(8,CONTRACHEQUE!$I$8:$I$87,0)),"")} | B40: {=IFERROR(INDEX(CONTRACHEQUE!$G$8:$G$87,MATCH(8,CONTRACHEQUE!$I$8:$I$87,0)),"")} | C40: {=IFERROR(INDEX(CONTRACHEQUE!$D$8:$D$87,MATCH(8,CONTRACHEQUE!$I$8:$I$87,0)),"")} | D40: =IF(C40="","",C40*$Z$4) | E40: =IF(C40="","",C40-D40) | F40: =IF(C40="","",C40*INDEX($Z$12:$Z$14,MATCH(B40,$A$12:$A$14,0))) | G40: =IF(C40="","",C40-F40)
A41: {=IFERROR(INDEX(CONTRACHEQUE!$B$8:$B$87,MATCH(9,CONTRACHEQUE!$I$8:$I$87,0)),"")} | B41: {=IFERROR(INDEX(CONTRACHEQUE!$G$8:$G$87,MATCH(9,CONTRACHEQUE!$I$8:$I$87,0)),"")} | C41: {=IFERROR(INDEX(CONTRACHEQUE!$D$8:$D$87,MATCH(9,CONTRACHEQUE!$I$8:$I$87,0)),"")} | D41: =IF(C41="","",C41*$Z$4) | E41: =IF(C41="","",C41-D41) | F41: =IF(C41="","",C41*INDEX($Z$12:$Z$14,MATCH(B41,$A$12:$A$14,0))) | G41: =IF(C41="","",C41-F41)
A42: {=IFERROR(INDEX(CONTRACHEQUE!$B$8:$B$87,MATCH(10,CONTRACHEQUE!$I$8:$I$87,0)),"")} | B42: {=IFERROR(INDEX(CONTRACHEQUE!$G$8:$G$87,MATCH(10,CONTRACHEQUE!$I$8:$I$87,0)),"")} | C42: {=IFERROR(INDEX(CONTRACHEQUE!$D$8:$D$87,MATCH(10,CONTRACHEQUE!$I$8:$I$87,0)),"")} | D42: =IF(C42="","",C42*$Z$4) | E42: =IF(C42="","",C42-D42) | F42: =IF(C42="","",C42*INDEX($Z$12:$Z$14,MATCH(B42,$A$12:$A$14,0))) | G42: =IF(C42="","",C42-F42)
A43: {=IFERROR(INDEX(CONTRACHEQUE!$B$8:$B$87,MATCH(11,CONTRACHEQUE!$I$8:$I$87,0)),"")} | B43: {=IFERROR(INDEX(CONTRACHEQUE!$G$8:$G$87,MATCH(11,CONTRACHEQUE!$I$8:$I$87,0)),"")} | C43: {=IFERROR(INDEX(CONTRACHEQUE!$D$8:$D$87,MATCH(11,CONTRACHEQUE!$I$8:$I$87,0)),"")} | D43: =IF(C43="","",C43*$Z$4) | E43: =IF(C43="","",C43-D43) | F43: =IF(C43="","",C43*INDEX($Z$12:$Z$14,MATCH(B43,$A$12:$A$14,0))) | G43: =IF(C43="","",C43-F43)
A44: {=IFERROR(INDEX(CONTRACHEQUE!$B$8:$B$87,MATCH(12,CONTRACHEQUE!$I$8:$I$87,0)),"")} | B44: {=IFERROR(INDEX(CONTRACHEQUE!$G$8:$G$87,MATCH(12,CONTRACHEQUE!$I$8:$I$87,0)),"")} | C44: {=IFERROR(INDEX(CONTRACHEQUE!$D$8:$D$87,MATCH(12,CONTRACHEQUE!$I$8:$I$87,0)),"")} | D44: =IF(C44="","",C44*$Z$4) | E44: =IF(C44="","",C44-D44) | F44: =IF(C44="","",C44*INDEX($Z$12:$Z$14,MATCH(B44,$A$12:$A$14,0))) | G44: =IF(C44="","",C44-F44)
A45: {=IFERROR(INDEX(CONTRACHEQUE!$B$8:$B$87,MATCH(13,CONTRACHEQUE!$I$8:$I$87,0)),"")} | B45: {=IFERROR(INDEX(CONTRACHEQUE!$G$8:$G$87,MATCH(13,CONTRACHEQUE!$I$8:$I$87,0)),"")} | C45: {=IFERROR(INDEX(CONTRACHEQUE!$D$8:$D$87,MATCH(13,CONTRACHEQUE!$I$8:$I$87,0)),"")} | D45: =IF(C45="","",C45*$Z$4) | E45: =IF(C45="","",C45-D45) | F45: =IF(C45="","",C45*INDEX($Z$12:$Z$14,MATCH(B45,$A$12:$A$14,0))) | G45: =IF(C45="","",C45-F45)
A46: {=IFERROR(INDEX(CONTRACHEQUE!$B$8:$B$87,MATCH(14,CONTRACHEQUE!$I$8:$I$87,0)),"")} | B46: {=IFERROR(INDEX(CONTRACHEQUE!$G$8:$G$87,MATCH(14,CONTRACHEQUE!$I$8:$I$87,0)),"")} | C46: {=IFERROR(INDEX(CONTRACHEQUE!$D$8:$D$87,MATCH(14,CONTRACHEQUE!$I$8:$I$87,0)),"")} | D46: =IF(C46="","",C46*$Z$4) | E46: =IF(C46="","",C46-D46) | F46: =IF(C46="","",C46*INDEX($Z$12:$Z$14,MATCH(B46,$A$12:$A$14,0))) | G46: =IF(C46="","",C46-F46)
A47: {=IFERROR(INDEX(CONTRACHEQUE!$B$8:$B$87,MATCH(15,CONTRACHEQUE!$I$8:$I$87,0)),"")} | B47: {=IFERROR(INDEX(CONTRACHEQUE!$G$8:$G$87,MATCH(15,CONTRACHEQUE!$I$8:$I$87,0)),"")} | C47: {=IFERROR(INDEX(CONTRACHEQUE!$D$8:$D$87,MATCH(15,CONTRACHEQUE!$I$8:$I$87,0)),"")} | D47: =IF(C47="","",C47*$Z$4) | E47: =IF(C47="","",C47-D47) | F47: =IF(C47="","",C47*INDEX($Z$12:$Z$14,MATCH(B47,$A$12:$A$14,0))) | G47: =IF(C47="","",C47-F47)
...

Sheet SE 40%
A1: ANÁLISE SEGMENTADA DE SITUAÇÃO FINANCEIRA
A3: ="READEQUAÇÃO DE MARGEM — "&IF(CONTRACHEQUE!$B$3="","[CLIENTE]",UPPER(CONTRACHEQUE!$B$3))&IF(CONTRACHEQUE!$B$5="",""," — COMPETÊNCIA "&CONTRACHEQUE!$B$5) -> READEQUAÇÃO DE MARGEM — [CLIENTE] | G3: DESCONTOS OBRIGATÓRIOS | J3: CONSIGNAÇÕES — TETO GLOBAL DE 40% (DECRETO 50.516/2026, ART. 10)
A4: Renda bruta: | B4: =H23 -> 0 | G4: Rubrica | H4: Valor | J4: Rubrica / Instituição | K4: Modalidade | L4: Desconto mensal
G5: {=IFERROR(INDEX(CONTRACHEQUE!$B$8:$B$87,MATCH(1,CONTRACHEQUE!$H$8:$H$87,0)),"")} | H5: {=IFERROR(INDEX(CONTRACHEQUE!$D$8:$D$87,MATCH(1,CONTRACHEQUE!$H$8:$H$87,0)),"")} | J5: {=IFERROR(INDEX(CONTRACHEQUE!$B$8:$B$87,MATCH(1,CONTRACHEQUE!$I$8:$I$87,0)),"")} | K5: {=IFERROR(INDEX(CONTRACHEQUE!$G$8:$G$87,MATCH(1,CONTRACHEQUE!$I$8:$I$87,0)),"")} | L5: {=IFERROR(INDEX(CONTRACHEQUE!$D$8:$D$87,MATCH(1,CONTRACHEQUE!$I$8:$I$87,0)),"")}
A6: Descontos obrigatórios: | B6: =H20 -> 0 | G6: {=IFERROR(INDEX(CONTRACHEQUE!$B$8:$B$87,MATCH(2,CONTRACHEQUE!$H$8:$H$87,0)),"")} | H6: {=IFERROR(INDEX(CONTRACHEQUE!$D$8:$D$87,MATCH(2,CONTRACHEQUE!$H$8:$H$87,0)),"")} | J6: {=IFERROR(INDEX(CONTRACHEQUE!$B$8:$B$87,MATCH(2,CONTRACHEQUE!$I$8:$I$87,0)),"")} | K6: {=IFERROR(INDEX(CONTRACHEQUE!$G$8:$G$87,MATCH(2,CONTRACHEQUE!$I$8:$I$87,0)),"")} | L6: {=IFERROR(INDEX(CONTRACHEQUE!$D$8:$D$87,MATCH(2,CONTRACHEQUE!$I$8:$I$87,0)),"")}
G7: {=IFERROR(INDEX(CONTRACHEQUE!$B$8:$B$87,MATCH(3,CONTRACHEQUE!$H$8:$H$87,0)),"")} | H7: {=IFERROR(INDEX(CONTRACHEQUE!$D$8:$D$87,MATCH(3,CONTRACHEQUE!$H$8:$H$87,0)),"")} | J7: {=IFERROR(INDEX(CONTRACHEQUE!$B$8:$B$87,MATCH(3,CONTRACHEQUE!$I$8:$I$87,0)),"")} | K7: {=IFERROR(INDEX(CONTRACHEQUE!$G$8:$G$87,MATCH(3,CONTRACHEQUE!$I$8:$I$87,0)),"")} | L7: {=IFERROR(INDEX(CONTRACHEQUE!$D$8:$D$87,MATCH(3,CONTRACHEQUE!$I$8:$I$87,0)),"")}
A8: Renda líquida: | B8: =B4-B6 -> 0 | C8: 1 | G8: {=IFERROR(INDEX(CONTRACHEQUE!$B$8:$B$87,MATCH(4,CONTRACHEQUE!$H$8:$H$87,0)),"")} | H8: {=IFERROR(INDEX(CONTRACHEQUE!$D$8:$D$87,MATCH(4,CONTRACHEQUE!$H$8:$H$87,0)),"")} | J8: {=IFERROR(INDEX(CONTRACHEQUE!$B$8:$B$87,MATCH(4,CONTRACHEQUE!$I$8:$I$87,0)),"")} | K8: {=IFERROR(INDEX(CONTRACHEQUE!$G$8:$G$87,MATCH(4,CONTRACHEQUE!$I$8:$I$87,0)),"")} | L8: {=IFERROR(INDEX(CONTRACHEQUE!$D$8:$D$87,MATCH(4,CONTRACHEQUE!$I$8:$I$87,0)),"")}
G9: {=IFERROR(INDEX(CONTRACHEQUE!$B$8:$B$87,MATCH(5,CONTRACHEQUE!$H$8:$H$87,0)),"")} | H9: {=IFERROR(INDEX(CONTRACHEQUE!$D$8:$D$87,MATCH(5,CONTRACHEQUE!$H$8:$H$87,0)),"")} | J9: {=IFERROR(INDEX(CONTRACHEQUE!$B$8:$B$87,MATCH(5,CONTRACHEQUE!$I$8:$I$87,0)),"")} | K9: {=IFERROR(INDEX(CONTRACHEQUE!$G$8:$G$87,MATCH(5,CONTRACHEQUE!$I$8:$I$87,0)),"")} | L9: {=IFERROR(INDEX(CONTRACHEQUE!$D$8:$D$87,MATCH(5,CONTRACHEQUE!$I$8:$I$87,0)),"")}
A10: Consignações dentro da margem de 40%: | B10: =MIN(B13,B8*$H$24) -> 0 | C10: =IF($B$8=0,0,B10/$B$8) -> 0 | G10: {=IFERROR(INDEX(CONTRACHEQUE!$B$8:$B$87,MATCH(6,CONTRACHEQUE!$H$8:$H$87,0)),"")} | H10: {=IFERROR(INDEX(CONTRACHEQUE!$D$8:$D$87,MATCH(6,CONTRACHEQUE!$H$8:$H$87,0)),"")} | J10: {=IFERROR(INDEX(CONTRACHEQUE!$B$8:$B$87,MATCH(6,CONTRACHEQUE!$I$8:$I$87,0)),"")} | K10: {=IFERROR(INDEX(CONTRACHEQUE!$G$8:$G$87,MATCH(6,CONTRACHEQUE!$I$8:$I$87,0)),"")} | L10: {=IFERROR(INDEX(CONTRACHEQUE!$D$8:$D$87,MATCH(6,CONTRACHEQUE!$I$8:$I$87,0)),"")}
A11: EXCESSO acima da margem de 40%: | B11: =MAX(0,B13-B8*$H$24) -> 0 | C11: =IF($B$8=0,0,B11/$B$8) -> 0 | G11: {=IFERROR(INDEX(CONTRACHEQUE!$B$8:$B$87,MATCH(7,CONTRACHEQUE!$H$8:$H$87,0)),"")} | H11: {=IFERROR(INDEX(CONTRACHEQUE!$D$8:$D$87,MATCH(7,CONTRACHEQUE!$H$8:$H$87,0)),"")} | J11: {=IFERROR(INDEX(CONTRACHEQUE!$B$8:$B$87,MATCH(7,CONTRACHEQUE!$I$8:$I$87,0)),"")} | K11: {=IFERROR(INDEX(CONTRACHEQUE!$G$8:$G$87,MATCH(7,CONTRACHEQUE!$I$8:$I$87,0)),"")} | L11: {=IFERROR(INDEX(CONTRACHEQUE!$D$8:$D$87,MATCH(7,CONTRACHEQUE!$I$8:$I$87,0)),"")}
A12: Total livre: | B12: =B8-B13 -> 0 | C12: =IF($B$8=0,0,B12/$B$8) -> 0 | G12: {=IFERROR(INDEX(CONTRACHEQUE!$B$8:$B$87,MATCH(8,CONTRACHEQUE!$H$8:$H$87,0)),"")} | H12: {=IFERROR(INDEX(CONTRACHEQUE!$D$8:$D$87,MATCH(8,CONTRACHEQUE!$H$8:$H$87,0)),"")} | J12: {=IFERROR(INDEX(CONTRACHEQUE!$B$8:$B$87,MATCH(8,CONTRACHEQUE!$I$8:$I$87,0)),"")} | K12: {=IFERROR(INDEX(CONTRACHEQUE!$G$8:$G$87,MATCH(8,CONTRACHEQUE!$I$8:$I$87,0)),"")} | L12: {=IFERROR(INDEX(CONTRACHEQUE!$D$8:$D$87,MATCH(8,CONTRACHEQUE!$I$8:$I$87,0)),"")}
A13: Total de consignações (emp. + cartões): | B13: =L20 -> 0 | C13: =IF($B$8=0,0,B13/$B$8) -> 0 | G13: {=IFERROR(INDEX(CONTRACHEQUE!$B$8:$B$87,MATCH(9,CONTRACHEQUE!$H$8:$H$87,0)),"")} | H13: {=IFERROR(INDEX(CONTRACHEQUE!$D$8:$D$87,MATCH(9,CONTRACHEQUE!$H$8:$H$87,0)),"")} | J13: {=IFERROR(INDEX(CONTRACHEQUE!$B$8:$B$87,MATCH(9,CONTRACHEQUE!$I$8:$I$87,0)),"")} | K13: {=IFERROR(INDEX(CONTRACHEQUE!$G$8:$G$87,MATCH(9,CONTRACHEQUE!$I$8:$I$87,0)),"")} | L13: {=IFERROR(INDEX(CONTRACHEQUE!$D$8:$D$87,MATCH(9,CONTRACHEQUE!$I$8:$I$87,0)),"")}
G14: {=IFERROR(INDEX(CONTRACHEQUE!$B$8:$B$87,MATCH(10,CONTRACHEQUE!$H$8:$H$87,0)),"")} | H14: {=IFERROR(INDEX(CONTRACHEQUE!$D$8:$D$87,MATCH(10,CONTRACHEQUE!$H$8:$H$87,0)),"")} | J14: {=IFERROR(INDEX(CONTRACHEQUE!$B$8:$B$87,MATCH(10,CONTRACHEQUE!$I$8:$I$87,0)),"")} | K14: {=IFERROR(INDEX(CONTRACHEQUE!$G$8:$G$87,MATCH(10,CONTRACHEQUE!$I$8:$I$87,0)),"")} | L14: {=IFERROR(INDEX(CONTRACHEQUE!$D$8:$D$87,MATCH(10,CONTRACHEQUE!$I$8:$I$87,0)),"")}
A15: =C13 -> 0 | B15: DA RENDA LÍQUIDA COMPROMETIDA COM CONSIGNAÇÕES | G15: {=IFERROR(INDEX(CONTRACHEQUE!$B$8:$B$87,MATCH(11,CONTRACHEQUE!$H$8:$H$87,0)),"")} | H15: {=IFERROR(INDEX(CONTRACHEQUE!$D$8:$D$87,MATCH(11,CONTRACHEQUE!$H$8:$H$87,0)),"")} | J15: {=IFERROR(INDEX(CONTRACHEQUE!$B$8:$B$87,MATCH(11,CONTRACHEQUE!$I$8:$I$87,0)),"")} | K15: {=IFERROR(INDEX(CONTRACHEQUE!$G$8:$G$87,MATCH(11,CONTRACHEQUE!$I$8:$I$87,0)),"")} | L15: {=IFERROR(INDEX(CONTRACHEQUE!$D$8:$D$87,MATCH(11,CONTRACHEQUE!$I$8:$I$87,0)),"")}
G16: {=IFERROR(INDEX(CONTRACHEQUE!$B$8:$B$87,MATCH(12,CONTRACHEQUE!$H$8:$H$87,0)),"")} | H16: {=IFERROR(INDEX(CONTRACHEQUE!$D$8:$D$87,MATCH(12,CONTRACHEQUE!$H$8:$H$87,0)),"")} | J16: {=IFERROR(INDEX(CONTRACHEQUE!$B$8:$B$87,MATCH(12,CONTRACHEQUE!$I$8:$I$87,0)),"")} | K16: {=IFERROR(INDEX(CONTRACHEQUE!$G$8:$G$87,MATCH(12,CONTRACHEQUE!$I$8:$I$87,0)),"")} | L16: {=IFERROR(INDEX(CONTRACHEQUE!$D$8:$D$87,MATCH(12,CONTRACHEQUE!$I$8:$I$87,0)),"")}
G17: {=IFERROR(INDEX(CONTRACHEQUE!$B$8:$B$87,MATCH(13,CONTRACHEQUE!$H$8:$H$87,0)),"")} | H17: {=IFERROR(INDEX(CONTRACHEQUE!$D$8:$D$87,MATCH(13,CONTRACHEQUE!$H$8:$H$87,0)),"")} | J17: {=IFERROR(INDEX(CONTRACHEQUE!$B$8:$B$87,MATCH(13,CONTRACHEQUE!$I$8:$I$87,0)),"")} | K17: {=IFERROR(INDEX(CONTRACHEQUE!$G$8:$G$87,MATCH(13,CONTRACHEQUE!$I$8:$I$87,0)),"")} | L17: {=IFERROR(INDEX(CONTRACHEQUE!$D$8:$D$87,MATCH(13,CONTRACHEQUE!$I$8:$I$87,0)),"")}
G18: {=IFERROR(INDEX(CONTRACHEQUE!$B$8:$B$87,MATCH(14,CONTRACHEQUE!$H$8:$H$87,0)),"")} | H18: {=IFERROR(INDEX(CONTRACHEQUE!$D$8:$D$87,MATCH(14,CONTRACHEQUE!$H$8:$H$87,0)),"")} | J18: {=IFERROR(INDEX(CONTRACHEQUE!$B$8:$B$87,MATCH(14,CONTRACHEQUE!$I$8:$I$87,0)),"")} | K18: {=IFERROR(INDEX(CONTRACHEQUE!$G$8:$G$87,MATCH(14,CONTRACHEQUE!$I$8:$I$87,0)),"")} | L18: {=IFERROR(INDEX(CONTRACHEQUE!$D$8:$D$87,MATCH(14,CONTRACHEQUE!$I$8:$I$87,0)),"")}
G19: {=IFERROR(INDEX(CONTRACHEQUE!$B$8:$B$87,MATCH(15,CONTRACHEQUE!$H$8:$H$87,0)),"")} | H19: {=IFERROR(INDEX(CONTRACHEQUE!$D$8:$D$87,MATCH(15,CONTRACHEQUE!$H$8:$H$87,0)),"")} | J19: {=IFERROR(INDEX(CONTRACHEQUE!$B$8:$B$87,MATCH(15,CONTRACHEQUE!$I$8:$I$87,0)),"")} | K19: {=IFERROR(INDEX(CONTRACHEQUE!$G$8:$G$87,MATCH(15,CONTRACHEQUE!$I$8:$I$87,0)),"")} | L19: {=IFERROR(INDEX(CONTRACHEQUE!$D$8:$D$87,MATCH(15,CONTRACHEQUE!$I$8:$I$87,0)),"")}
G20: TOTAL | H20: =SUMIF(CONTRACHEQUE!$G$8:$G$87,"DESCONTO OBRIGATÓRIO",CONTRACHEQUE!$D$8:$D$87) -> 0 | J20: TOTAL | L20: =SUMIF(CONTRACHEQUE!$G$8:$G$87,"EMPRÉSTIMO CONSIGNADO",CONTRACHEQUE!$D$8:$D$87)+SUMIF(CONTRACHEQUE!$G$8:$G$87,"CARTÃO CONSIGNADO",CONTRACHEQUE!$D$8:$D$87)+SUMIF(CONTRACHEQUE!$G$8:$G$87,"CARTÃO BENEFÍCIO",CONTRACHEQUE!$D$8:$D$87) -> 0
K21: EMPRÉSTIMO CONSIGNADO | L21: =SUMIF(CONTRACHEQUE!$G$8:$G$87,K21,CONTRACHEQUE!$D$8:$D$87) -> 0
G22: PARÂMETROS | K22: CARTÃO CONSIGNADO | L22: =SUMIF(CONTRACHEQUE!$G$8:$G$87,K22,CONTRACHEQUE!$D$8:$D$87) -> 0
G23: Renda bruta (proventos) | H23: =SUMIF(CONTRACHEQUE!$G$8:$G$87,"PROVENTO",CONTRACHEQUE!$D$8:$D$87) -> 0 | K23: CARTÃO BENEFÍCIO | L23: =SUMIF(CONTRACHEQUE!$G$8:$G$87,K23,CONTRACHEQUE!$D$8:$D$87) -> 0
G24: Teto global — Decreto 50.516/2026, art. 10 | H24: 0.4
G26: =IF(CONTRACHEQUE!$D$92>0,"ATENÇÃO: "&CONTRACHEQUE!$D$92&" rubrica(s) pendente(s) de revisão na aba CONTRACHEQUE.",IF(COUNTIF(CONTRACHEQUE!$H$8:$H$87,">"&15)+COUNTIF(CONTRACHEQUE!$I$8:$I$87,">"&15)>0,"ATENÇÃO: há mais de 15 itens em uma das listas — os totais estão corretos, mas nem todos aparecem no quadro.","✔ Todas as rubricas classificadas.")) -> ✔ Todas as rubricas classificadas.
A35: DÍVIDA MENSAL ATUAL (consignações): | B35: =B13 -> 0 | C35: REDUÇÃO MENSAL DE PRESTAÇÃO: | E35: =B35-B36 -> 0
A36: DÍVIDA MENSAL APÓS PROCESSO (40%): | B36: =MIN(B13,B8*$H$24) -> 0
A37: EXPECTATIVA DE RENDA LIVRE: | B37: =B12+E35 -> 0
A39: • Empréstimos pessoais não entram: classifique-os como EMPRÉSTIMO PESSOAL ou NÃO CONSIDERAR na aba CONTRACHEQUE.
A40: • Teto global de 40% sobre a renda líquida (art. 10, caput, e art. 11 do Decreto nº 50.516/2026), abrangendo empréstimo consignado, cartão de crédito consignado e cartão benefício.
A41: • Esta aba é 100% automática: alimente apenas a aba CONTRACHEQUE (e, se quiser, o percentual da margem em amarelo).

Sheet SE 35-5
A1: ANÁLISE SEGMENTADA DE SITUAÇÃO FINANCEIRA
A3: ="CENÁRIO B (35% + 5%) — "&IF(CONTRACHEQUE!$B$3="","[CLIENTE]",UPPER(CONTRACHEQUE!$B$3))&IF(CONTRACHEQUE!$B$5="",""," — COMPETÊNCIA "&CONTRACHEQUE!$B$5) -> CENÁRIO B (35% + 5%) — [CLIENTE] | G3: CONSIGNAÇÕES — MARGENS SEGMENTADAS (DECRETO 50.516/2026, ART. 10, I E II)
A4: Renda bruta: | B4: =SUMIF(CONTRACHEQUE!$G$8:$G$87,"PROVENTO",CONTRACHEQUE!$D$8:$D$87) -> 0 | G4: Modalidade | H4: Desconto atual | I4: % da renda líquida | J4: Margem legal (%) | K4: Margem legal (R$) | L4: Excesso | M4: Situação
G5: EMPRÉSTIMO CONSIGNADO | H5: =SUMIF(CONTRACHEQUE!$G$8:$G$87,"EMPRÉSTIMO CONSIGNADO",CONTRACHEQUE!$D$8:$D$87) -> 0 | I5: =IF($B$8=0,0,H5/$B$8) -> 0 | J5: 0.35 | K5: =$B$8*J5 -> 0 | L5: =MAX(0,H5+H7-K5) -> 0 | M5: =IF(H5+H7=0,"—",IF(L5>0,"ACIMA DA MARGEM","Dentro da margem")) -> —
A6: Descontos obrigatórios: | B6: =SUMIF(CONTRACHEQUE!$G$8:$G$87,"DESCONTO OBRIGATÓRIO",CONTRACHEQUE!$D$8:$D$87) -> 0 | G6: CARTÃO CONSIGNADO | H6: =SUMIF(CONTRACHEQUE!$G$8:$G$87,"CARTÃO CONSIGNADO",CONTRACHEQUE!$D$8:$D$87) -> 0 | I6: =IF($B$8=0,0,H6/$B$8) -> 0 | J6: 0.05 | K6: =$B$8*J6 -> 0 | L6: =MAX(0,H6-K6) -> 0 | M6: =IF(H6=0,"—",IF(L6>0,"ACIMA DA MARGEM","Dentro da margem")) -> —
G7: CARTÃO BENEFÍCIO | H7: =SUMIF(CONTRACHEQUE!$G$8:$G$87,"CARTÃO BENEFÍCIO",CONTRACHEQUE!$D$8:$D$87) -> 0 | I7: =IF($B$8=0,0,H7/$B$8) -> 0 | J7: =J5 -> 0.35 | K7: ="(incl. nos 35%)" -> (incl. nos 35%) | L7: =0 -> 0 | M7: =IF(H7=0,"—",IF(L5>0,"ACIMA DA MARGEM (35%)","Dentro da margem")) -> —
A8: Renda líquida: | B8: =B4-B6 -> 0 | C8: 1 | G8: TOTAL | H8: =SUM(H5:H7) -> 0 | I8: =IF($B$8=0,0,H8/$B$8) -> 0 | J8: =J5+J6 -> 0.4 | K8: =SUM(K5:K7) -> 0 | L8: =SUM(L5:L7) -> 0 | M8: =IF(L8>0,"HÁ EXCESSO","Sem excesso") -> Sem excesso
A10: Consignações dentro das margens (35% + 5%): | B10: =H8-L8 -> 0 | C10: =IF($B$8=0,0,B10/$B$8) -> 0 | G10: ='SE 40%'!G26 -> ✔ Todas as rubricas classificadas.
A11: EXCESSO acima das margens segmentadas: | B11: =L8 -> 0 | C11: =IF($B$8=0,0,B11/$B$8) -> 0
A12: Total livre: | B12: =B8-B13 -> 0 | C12: =IF($B$8=0,0,B12/$B$8) -> 0
A13: Total de consignações (emp. + cartões): | B13: =H8 -> 0 | C13: =IF($B$8=0,0,B13/$B$8) -> 0 | G13: • Célula amarela (J5) = margem de 35% (empréstimo consignado + cartão benefício); J6 = 5% exclusivo do cartão de crédito consignado. Conforme art. 10, I e II, do Decreto Estadual nº 50.516/2026.
G14: • Empréstimo consignado e cartão benefício dividem a mesma margem de 35%; o cartão de crédito consignado tem margem própria de 5%, sem compensação com a folga dos 35%. Teto global: 40%.
A15: =C13 -> 0 | B15: DA RENDA LÍQUIDA COMPROMETIDA COM CONSIGNAÇÕES | G15: • Empréstimo pessoal não entra: classifique-o como EMPRÉSTIMO PESSOAL ou NÃO CONSIDERAR na aba CONTRACHEQUE.
A35: DÍVIDA MENSAL ATUAL (consignações): | B35: =B13 -> 0 | C35: REDUÇÃO MENSAL DE PRESTAÇÃO: | E35: =B35-B36 -> 0
A36: DÍVIDA MENSAL APÓS PROCESSO (35% + 5%): | B36: =B10 -> 0
A37: EXPECTATIVA DE RENDA LIVRE: | B37: =B12+E35 -> 0
A39: • Cenário B: margens segmentadas do Decreto nº 50.516/2026, art. 10, I e II — até 35% para empréstimo consignado e demais consignações facultativas (inclui o cartão benefício) e até 5% exclusivamente para o cartão de crédito consignado, sobre a renda líquida (art. 11).
A40: • Compare com o Cenário A (teto global de 40%, art. 10, caput) na aba SE 40% e no quadro da aba COMPARATIVO.
A41: • Esta aba é 100% automática: alimente apenas a aba CONTRACHEQUE (e, se quiser, os percentuais em amarelo).

Sheet CONTRACHEQUE
A1: CONTRACHEQUE — LANÇAMENTO DAS RUBRICAS
A3: Cliente: | E3: COMO USAR: cole/digite as rubricas do contracheque nas colunas A a D (Tipo: P = provento; D = desconto). A classificação é automática pela aba REGRAS. Se alguma aparecer como REVISAR, escolha a classificação na coluna F (manual), que prevalece sobre a automática.
A4: Órgão pagador:
A5: Competência:
A7: Código | B7: Descrição da rubrica | C7: Tipo (P/D) | D7: Valor (R$) | E7: Classificação automática | F7: Classificação manual (opcional) | G7: CLASSIFICAÇÃO FINAL
E8: {=IF(D8="","",IF(UPPER(C8)="P","PROVENTO",IF(C8="","INFORMAR TIPO",IFERROR(INDEX(REGRAS!$B$5:$B$118,MATCH(1,INDEX((REGRAS!$A$5:$A$118<>"")*ISNUMBER(SEARCH(REGRAS!$A$5:$A$118,B8)),0),0)),"REVISAR"))))} | G8: =IF(F8<>"",F8,E8) | H8: =IF(G8="DESCONTO OBRIGATÓRIO",COUNTIF($G$8:G8,"DESCONTO OBRIGATÓRIO"),"") | I8: =IF(OR(G8="EMPRÉSTIMO CONSIGNADO",G8="CARTÃO CONSIGNADO",G8="CARTÃO BENEFÍCIO"),COUNTIF($G$8:G8,"EMPRÉSTIMO CONSIGNADO")+COUNTIF($G$8:G8,"CARTÃO CONSIGNADO")+COUNTIF($G$8:G8,"CARTÃO BENEFÍCIO"),"")
E9: {=IF(D9="","",IF(UPPER(C9)="P","PROVENTO",IF(C9="","INFORMAR TIPO",IFERROR(INDEX(REGRAS!$B$5:$B$118,MATCH(1,INDEX((REGRAS!$A$5:$A$118<>"")*ISNUMBER(SEARCH(REGRAS!$A$5:$A$118,B9)),0),0)),"REVISAR"))))} | G9: =IF(F9<>"",F9,E9) | H9: =IF(G9="DESCONTO OBRIGATÓRIO",COUNTIF($G$8:G9,"DESCONTO OBRIGATÓRIO"),"") | I9: =IF(OR(G9="EMPRÉSTIMO CONSIGNADO",G9="CARTÃO CONSIGNADO",G9="CARTÃO BENEFÍCIO"),COUNTIF($G$8:G9,"EMPRÉSTIMO CONSIGNADO")+COUNTIF($G$8:G9,"CARTÃO CONSIGNADO")+COUNTIF($G$8:G9,"CARTÃO BENEFÍCIO"),"")
E10: {=IF(D10="","",IF(UPPER(C10)="P","PROVENTO",IF(C10="","INFORMAR TIPO",IFERROR(INDEX(REGRAS!$B$5:$B$118,MATCH(1,INDEX((REGRAS!$A$5:$A$118<>"")*ISNUMBER(SEARCH(REGRAS!$A$5:$A$118,B10)),0),0)),"REVISAR"))))} | G10: =IF(F10<>"",F10,E10) | H10: =IF(G10="DESCONTO OBRIGATÓRIO",COUNTIF($G$8:G10,"DESCONTO OBRIGATÓRIO"),"") | I10: =IF(OR(G10="EMPRÉSTIMO CONSIGNADO",G10="CARTÃO CONSIGNADO",G10="CARTÃO BENEFÍCIO"),COUNTIF($G$8:G10,"EMPRÉSTIMO CONSIGNADO")+COUNTIF($G$8:G10,"CARTÃO CONSIGNADO")+COUNTIF($G$8:G10,"CARTÃO BENEFÍCIO"),"")
E11: {=IF(D11="","",IF(UPPER(C11)="P","PROVENTO",IF(C11="","INFORMAR TIPO",IFERROR(INDEX(REGRAS!$B$5:$B$118,MATCH(1,INDEX((REGRAS!$A$5:$A$118<>"")*ISNUMBER(SEARCH(REGRAS!$A$5:$A$118,B11)),0),0)),"REVISAR"))))} | G11: =IF(F11<>"",F11,E11) | H11: =IF(G11="DESCONTO OBRIGATÓRIO",COUNTIF($G$8:G11,"DESCONTO OBRIGATÓRIO"),"") | I11: =IF(OR(G11="EMPRÉSTIMO CONSIGNADO",G11="CARTÃO CONSIGNADO",G11="CARTÃO BENEFÍCIO"),COUNTIF($G$8:G11,"EMPRÉSTIMO CONSIGNADO")+COUNTIF($G$8:G11,"CARTÃO CONSIGNADO")+COUNTIF($G$8:G11,"CARTÃO BENEFÍCIO"),"")
E12: {=IF(D12="","",IF(UPPER(C12)="P","PROVENTO",IF(C12="","INFORMAR TIPO",IFERROR(INDEX(REGRAS!$B$5:$B$118,MATCH(1,INDEX((REGRAS!$A$5:$A$118<>"")*ISNUMBER(SEARCH(REGRAS!$A$5:$A$118,B12)),0),0)),"REVISAR"))))} | G12: =IF(F12<>"",F12,E12) | H12: =IF(G12="DESCONTO OBRIGATÓRIO",COUNTIF($G$8:G12,"DESCONTO OBRIGATÓRIO"),"") | I12: =IF(OR(G12="EMPRÉSTIMO CONSIGNADO",G12="CARTÃO CONSIGNADO",G12="CARTÃO BENEFÍCIO"),COUNTIF($G$8:G12,"EMPRÉSTIMO CONSIGNADO")+COUNTIF($G$8:G12,"CARTÃO CONSIGNADO")+COUNTIF($G$8:G12,"CARTÃO BENEFÍCIO"),"")
E13: {=IF(D13="","",IF(UPPER(C13)="P","PROVENTO",IF(C13="","INFORMAR TIPO",IFERROR(INDEX(REGRAS!$B$5:$B$118,MATCH(1,INDEX((REGRAS!$A$5:$A$118<>"")*ISNUMBER(SEARCH(REGRAS!$A$5:$A$118,B13)),0),0)),"REVISAR"))))} | G13: =IF(F13<>"",F13,E13) | H13: =IF(G13="DESCONTO OBRIGATÓRIO",COUNTIF($G$8:G13,"DESCONTO OBRIGATÓRIO"),"") | I13: =IF(OR(G13="EMPRÉSTIMO CONSIGNADO",G13="CARTÃO CONSIGNADO",G13="CARTÃO BENEFÍCIO"),COUNTIF($G$8:G13,"EMPRÉSTIMO CONSIGNADO")+COUNTIF($G$8:G13,"CARTÃO CONSIGNADO")+COUNTIF($G$8:G13,"CARTÃO BENEFÍCIO"),"")
E14: {=IF(D14="","",IF(UPPER(C14)="P","PROVENTO",IF(C14="","INFORMAR TIPO",IFERROR(INDEX(REGRAS!$B$5:$B$118,MATCH(1,INDEX((REGRAS!$A$5:$A$118<>"")*ISNUMBER(SEARCH(REGRAS!$A$5:$A$118,B14)),0),0)),"REVISAR"))))} | G14: =IF(F14<>"",F14,E14) | H14: =IF(G14="DESCONTO OBRIGATÓRIO",COUNTIF($G$8:G14,"DESCONTO OBRIGATÓRIO"),"") | I14: =IF(OR(G14="EMPRÉSTIMO CONSIGNADO",G14="CARTÃO CONSIGNADO",G14="CARTÃO BENEFÍCIO"),COUNTIF($G$8:G14,"EMPRÉSTIMO CONSIGNADO")+COUNTIF($G$8:G14,"CARTÃO CONSIGNADO")+COUNTIF($G$8:G14,"CARTÃO BENEFÍCIO"),"")
E15: {=IF(D15="","",IF(UPPER(C15)="P","PROVENTO",IF(C15="","INFORMAR TIPO",IFERROR(INDEX(REGRAS!$B$5:$B$118,MATCH(1,INDEX((REGRAS!$A$5:$A$118<>"")*ISNUMBER(SEARCH(REGRAS!$A$5:$A$118,B15)),0),0)),"REVISAR"))))} | G15: =IF(F15<>"",F15,E15) | H15: =IF(G15="DESCONTO OBRIGATÓRIO",COUNTIF($G$8:G15,"DESCONTO OBRIGATÓRIO"),"") | I15: =IF(OR(G15="EMPRÉSTIMO CONSIGNADO",G15="CARTÃO CONSIGNADO",G15="CARTÃO BENEFÍCIO"),COUNTIF($G$8:G15,"EMPRÉSTIMO CONSIGNADO")+COUNTIF($G$8:G15,"CARTÃO CONSIGNADO")+COUNTIF($G$8:G15,"CARTÃO BENEFÍCIO"),"")
E16: {=IF(D16="","",IF(UPPER(C16)="P","PROVENTO",IF(C16="","INFORMAR TIPO",IFERROR(INDEX(REGRAS!$B$5:$B$118,MATCH(1,INDEX((REGRAS!$A$5:$A$118<>"")*ISNUMBER(SEARCH(REGRAS!$A$5:$A$118,B16)),0),0)),"REVISAR"))))} | G16: =IF(F16<>"",F16,E16) | H16: =IF(G16="DESCONTO OBRIGATÓRIO",COUNTIF($G$8:G16,"DESCONTO OBRIGATÓRIO"),"") | I16: =IF(OR(G16="EMPRÉSTIMO CONSIGNADO",G16="CARTÃO CONSIGNADO",G16="CARTÃO BENEFÍCIO"),COUNTIF($G$8:G16,"EMPRÉSTIMO CONSIGNADO")+COUNTIF($G$8:G16,"CARTÃO CONSIGNADO")+COUNTIF($G$8:G16,"CARTÃO BENEFÍCIO"),"")
E17: {=IF(D17="","",IF(UPPER(C17)="P","PROVENTO",IF(C17="","INFORMAR TIPO",IFERROR(INDEX(REGRAS!$B$5:$B$118,MATCH(1,INDEX((REGRAS!$A$5:$A$118<>"")*ISNUMBER(SEARCH(REGRAS!$A$5:$A$118,B17)),0),0)),"REVISAR"))))} | G17: =IF(F17<>"",F17,E17) | H17: =IF(G17="DESCONTO OBRIGATÓRIO",COUNTIF($G$8:G17,"DESCONTO OBRIGATÓRIO"),"") | I17: =IF(OR(G17="EMPRÉSTIMO CONSIGNADO",G17="CARTÃO CONSIGNADO",G17="CARTÃO BENEFÍCIO"),COUNTIF($G$8:G17,"EMPRÉSTIMO CONSIGNADO")+COUNTIF($G$8:G17,"CARTÃO CONSIGNADO")+COUNTIF($G$8:G17,"CARTÃO BENEFÍCIO"),"")
E18: {=IF(D18="","",IF(UPPER(C18)="P","PROVENTO",IF(C18="","INFORMAR TIPO",IFERROR(INDEX(REGRAS!$B$5:$B$118,MATCH(1,INDEX((REGRAS!$A$5:$A$118<>"")*ISNUMBER(SEARCH(REGRAS!$A$5:$A$118,B18)),0),0)),"REVISAR"))))} | G18: =IF(F18<>"",F18,E18) | H18: =IF(G18="DESCONTO OBRIGATÓRIO",COUNTIF($G$8:G18,"DESCONTO OBRIGATÓRIO"),"") | I18: =IF(OR(G18="EMPRÉSTIMO CONSIGNADO",G18="CARTÃO CONSIGNADO",G18="CARTÃO BENEFÍCIO"),COUNTIF($G$8:G18,"EMPRÉSTIMO CONSIGNADO")+COUNTIF($G$8:G18,"CARTÃO CONSIGNADO")+COUNTIF($G$8:G18,"CARTÃO BENEFÍCIO"),"")
E19: {=IF(D19="","",IF(UPPER(C19)="P","PROVENTO",IF(C19="","INFORMAR TIPO",IFERROR(INDEX(REGRAS!$B$5:$B$118,MATCH(1,INDEX((REGRAS!$A$5:$A$118<>"")*ISNUMBER(SEARCH(REGRAS!$A$5:$A$118,B19)),0),0)),"REVISAR"))))} | G19: =IF(F19<>"",F19,E19) | H19: =IF(G19="DESCONTO OBRIGATÓRIO",COUNTIF($G$8:G19,"DESCONTO OBRIGATÓRIO"),"") | I19: =IF(OR(G19="EMPRÉSTIMO CONSIGNADO",G19="CARTÃO CONSIGNADO",G19="CARTÃO BENEFÍCIO"),COUNTIF($G$8:G19,"EMPRÉSTIMO CONSIGNADO")+COUNTIF($G$8:G19,"CARTÃO CONSIGNADO")+COUNTIF($G$8:G19,"CARTÃO BENEFÍCIO"),"")
... E87: {=IF(D87="","",IF(UPPER(C87)="P","PROVENTO",IF(C87="","INFORMAR TIPO",IFERROR(INDEX(REGRAS!$B$5:$B$118,MATCH(1,INDEX((REGRAS!$A$5:$A$118<>"")*ISNUMBER(SEARCH(REGRAS!$A$5:$A$118,B87)),0),0)),"REVISAR"))))} | G87: =IF(F87<>"",F87,E87) | H87: =IF(G87="DESCONTO OBRIGATÓRIO",COUNTIF($G$8:G87,"DESCONTO OBRIGATÓRIO"),"") | I87: =IF(OR(G87="EMPRÉSTIMO CONSIGNADO",G87="CARTÃO CONSIGNADO",G87="CARTÃO BENEFÍCIO"),COUNTIF($G$8:G87,"EMPRÉSTIMO CONSIGNADO")+COUNTIF($G$8:G87,"CARTÃO CONSIGNADO")+COUNTIF($G$8:G87,"CARTÃO BENEFÍCIO"),"")
B89: Total de proventos | D89: =SUMIF($G$8:$G$87,"PROVENTO",$D$8:$D$87) -> 0
B90: Total de descontos obrigatórios | D90: =SUMIF($G$8:$G$87,"DESCONTO OBRIGATÓRIO",$D$8:$D$87) -> 0
B91: Total de consignações (emp. + cartões) | D91: =SUMIF($G$8:$G$87,"EMPRÉSTIMO CONSIGNADO",$D$8:$D$87)+SUMIF($G$8:$G$87,"CARTÃO CONSIGNADO",$D$8:$D$87)+SUMIF($G$8:$G$87,"CARTÃO BENEFÍCIO",$D$8:$D$87) -> 0
B92: Rubricas pendentes de revisão | D92: =COUNTIF($G$8:$G$87,"REVISAR")+COUNTIF($G$8:$G$87,"INFORMAR TIPO") -> 0

Sheet REGRAS
A1: REGRAS DE CLASSIFICAÇÃO AUTOMÁTICA DAS RUBRICAS
A2: A rubrica do contracheque é classificada pela PRIMEIRA palavra-chave desta lista que aparecer na descrição (ordem de cima para baixo = prioridade). Acrescente ou edite palavras-chave nas linhas livres. Rubricas lançadas como Provento (P) são classificadas automaticamente.
A4: Palavra-chave (contida na descrição) | B4: Classificação | C4: Observação
A5: CARTAO BENEF | B5: CARTÃO BENEFÍCIO | C5: Cartão benefício / RCC — antes do cartão consignado
A6: CARTÃO BENEF | B6: CARTÃO BENEFÍCIO | C6: Cartão benefício / RCC — antes do cartão consignado
A7: CART BENEF | B7: CARTÃO BENEFÍCIO | C7: Cartão benefício / RCC — antes do cartão consignado
A8: CART. BENEF | B8: CARTÃO BENEFÍCIO | C8: Cartão benefício / RCC — antes do cartão consignado
A9: CARTAO-BENEF | B9: CARTÃO BENEFÍCIO | C9: Cartão benefício / RCC — antes do cartão consignado
A10: BENEFICIO CART | B10: CARTÃO BENEFÍCIO | C10: Cartão benefício / RCC — antes do cartão consignado
A11: BENEFÍCIO CART | B11: CARTÃO BENEFÍCIO | C11: Cartão benefício / RCC — antes do cartão consignado
A12: RCC | B12: CARTÃO BENEFÍCIO | C12: Cartão benefício / RCC — antes do cartão consignado
A13: RMC | B13: CARTÃO CONSIGNADO | C13: Cartão de crédito consignado / RMC
A14: CARTAO | B14: CARTÃO CONSIGNADO | C14: Cartão de crédito consignado / RMC
A15: CARTÃO | B15: CARTÃO CONSIGNADO | C15: Cartão de crédito consignado / RMC
... A77: DETERM JUD | B77: DESCONTO OBRIGATÓRIO | C77: Tributos, previdência, saúde e determinações judiciais

Sheet LISTAS
A1: Classificações | C1: Tipo
A2: PROVENTO | C2: P
A3: DESCONTO OBRIGATÓRIO | C3: D
A4: EMPRÉSTIMO CONSIGNADO
A5: CARTÃO CONSIGNADO
A6: CARTÃO BENEFÍCIO
A7: EMPRÉSTIMO PESSOAL
A8: NÃO CONSIDERAR
